Traceback (most recent call last):
  File "/home/runner/viewmycoa/.pythonlibs/lib/python3.11/site-packages/flask/app.py", line 1536, in __call__
    return self.wsgi_app(environ, start_response)
           ^^^^^^^^^^^^^^^^^^^^^^^^^^^^^^^^^^^^^^
  File "/home/runner/viewmycoa/.pythonlibs/lib/python3.11/site-packages/flask/app.py", line 1514, in wsgi_app
    response = self.handle_exception(e)
               ^^^^^^^^^^^^^^^^^^^^^^^^
  File "/home/runner/viewmycoa/.pythonlibs/lib/python3.11/site-packages/flask/app.py", line 1511, in wsgi_app
    response = self.full_dispatch_request()
               ^^^^^^^^^^^^^^^^^^^^^^^^^^^^
  File "/home/runner/viewmycoa/.pythonlibs/lib/python3.11/site-packages/flask/app.py", line 919, in full_dispatch_request
    rv = self.handle_user_exception(e)
         ^^^^^^^^^^^^^^^^^^^^^^^^^^^^^
  File "/home/runner/viewmycoa/.pythonlibs/lib/python3.11/site-packages/flask/app.py", line 917, in full_dispatch_request
    rv = self.dispatch_request()
         ^^^^^^^^^^^^^^^^^^^^^^^
  File "/home/runner/viewmycoa/.pythonlibs/lib/python3.11/site-packages/flask/app.py", line 902, in dispatch_request
    return self.ensure_sync(self.view_functions[rule.endpoint])(**view_args)  # type: ignore[no-any-return]
           ^^^^^^^^^^^^^^^^^^^^^^^^^^^^^^^^^^^^^^^^^^^^^^^^^^^^^^^^^^^^^^^^^^^^^^^^^^^^^^^^^^^^^^^^^^^^^^^^
  File "/home/runner/viewmycoa/app.py", line 92, in admin_dashboard
    products = models.Product.query.all()
               ^^^^^^^^^^^^^^^^^^^^^^^^^^
  File "/home/runner/viewmycoa/.pythonlibs/lib/python3.11/site-packages/flask_sqlalchemy/model.py", line 22, in __get__
    return cls.query_class(
           ^^^^^^^^^^^^^^^^
  File "/home/runner/viewmycoa/.pythonlibs/lib/python3.11/site-packages/sqlalchemy/orm/query.py", line 275, in __init__
    self._set_entities(entities)
  File "/home/runner/viewmycoa/.pythonlibs/lib/python3.11/site-packages/sqlalchemy/orm/query.py", line 287, in _set_entities
    self._raw_columns = [
                        ^
  File "/home/runner/viewmycoa/.pythonlibs/lib/python3.11/site-packages/sqlalchemy/orm/query.py", line 288, in <listcomp>
    coercions.expect(
  File "/home/runner/viewmycoa/.pythonlibs/lib/python3.11/site-packages/sqlalchemy/sql/coercions.py", line 388, in expect
    insp._post_inspect
  File "/home/runner/viewmycoa/.pythonlibs/lib/python3.11/site-packages/sqlalchemy/util/langhelpers.py", line 1253, in __get__
    obj.__dict__[self.__name__] = result = self.fget(obj)
                                           ^^^^^^^^^^^^^^
  File "/home/runner/viewmycoa/.pythonlibs/lib/python3.11/site-packages/sqlalchemy/orm/mapper.py", line 2722, in _post_inspect
    self._check_configure()
  File "/home/runner/viewmycoa/.pythonlibs/lib/python3.11/site-packages/sqlalchemy/orm/mapper.py", line 2399, in _check_configure
    _configure_registries({self.registry}, cascade=True)
  File "/home/runner/viewmycoa/.pythonlibs/lib/python3.11/site-packages/sqlalchemy/orm/mapper.py", line 4215, in _configure_registries
    _do_configure_registries(registries, cascade)
  File "/home/runner/viewmycoa/.pythonlibs/lib/python3.11/site-packages/sqlalchemy/orm/mapper.py", line 4256, in _do_configure_registries
    mapper._post_configure_properties()
  File "/home/runner/viewmycoa/.pythonlibs/lib/python3.11/site-packages/sqlalchemy/orm/mapper.py", line 2416, in _post_configure_properties
    prop.init()
  File "/home/runner/viewmycoa/.pythonlibs/lib/python3.11/site-packages/sqlalchemy/orm/interfaces.py", line 589, in init
    self.do_init()
  File "/home/runner/viewmycoa/.pythonlibs/lib/python3.11/site-packages/sqlalchemy/orm/relationships.py", line 1647, in do_init
    self._generate_backref()
  File "/home/runner/viewmycoa/.pythonlibs/lib/python3.11/site-packages/sqlalchemy/orm/relationships.py", line 2075, in _generate_backref
    raise sa_exc.ArgumentError(
sqlalchemy.exc.ArgumentError: Error creating backref 'categories' on relationship 'Category.products': property of that name exists on mapper 'Mapper[Product(product)]'