Traceback (most recent call last):
  File "/home/runner/viewmycoa/.pythonlibs/bin/flask", line 8, in <module>
    sys.exit(main())
             ^^^^^^
  File "/home/runner/viewmycoa/.pythonlibs/lib/python3.11/site-packages/flask/cli.py", line 1129, in main
    cli.main()
  File "/home/runner/viewmycoa/.pythonlibs/lib/python3.11/site-packages/click/core.py", line 1078, in main
    rv = self.invoke(ctx)
         ^^^^^^^^^^^^^^^^
  File "/home/runner/viewmycoa/.pythonlibs/lib/python3.11/site-packages/click/core.py", line 1682, in invoke
    cmd_name, cmd, args = self.resolve_command(ctx, args)
                          ^^^^^^^^^^^^^^^^^^^^^^^^^^^^^^^
  File "/home/runner/viewmycoa/.pythonlibs/lib/python3.11/site-packages/click/core.py", line 1729, in resolve_command
    cmd = self.get_command(ctx, cmd_name)
          ^^^^^^^^^^^^^^^^^^^^^^^^^^^^^^^
  File "/home/runner/viewmycoa/.pythonlibs/lib/python3.11/site-packages/flask/cli.py", line 631, in get_command
    app = info.load_app()
          ^^^^^^^^^^^^^^^
  File "/home/runner/viewmycoa/.pythonlibs/lib/python3.11/site-packages/flask/cli.py", line 349, in load_app
    app = locate_app(import_name, name)
          ^^^^^^^^^^^^^^^^^^^^^^^^^^^^^
  File "/home/runner/viewmycoa/.pythonlibs/lib/python3.11/site-packages/flask/cli.py", line 245, in locate_app
    __import__(module_name)
  File "/home/runner/viewmycoa/app.py", line 26, in <module>
    db.create_all()
  File "/home/runner/viewmycoa/.pythonlibs/lib/python3.11/site-packages/flask_sqlalchemy/extension.py", line 900, in create_all
    self._call_for_binds(bind_key, "create_all")
  File "/home/runner/viewmycoa/.pythonlibs/lib/python3.11/site-packages/flask_sqlalchemy/extension.py", line 871, in _call_for_binds
    engine = self.engines[key]
             ^^^^^^^^^^^^
  File "/home/runner/viewmycoa/.pythonlibs/lib/python3.11/site-packages/flask_sqlalchemy/extension.py", line 690, in engines
    raise RuntimeError(
RuntimeError: The current Flask app is not registered with this 'SQLAlchemy' instance. Did you forget to call 'init_app', or did you create multiple 'SQLAlchemy' instances?
